------------
 2019-06-01 15:54:53,552 - vk_exception_h - ERROR - error uploader_to_yandex_storage_h 
Traceback (most recent call last):
  File "<ipython-input-2-8cf6b50de5fc>", line 5, in <module>
    img_to_upload = utils_db.select_img_to_yandex_storage_upload()
  File "data/utils_db.py", line 58, in select_img_to_yandex_storage_upload
    with closing(psycopg2.connect(**params_db)) as conn:
  File "/usr/local/lib/python3.6/dist-packages/psycopg2/__init__.py", line 126, in connect
    conn = _connect(dsn, connection_factory=connection_factory, **kwasync)
psycopg2.OperationalError: could not connect to server: Connection refused
	Is the server running on host "rc1a-sgxb6yanrh3pkjcs.mdb.yandexcloud.net" (10.128.0.6) and accepting
	TCP/IP connections on port 6432?

------------
 2019-06-01 15:54:53,695 - vk_exception_h - ERROR - error uploader_to_yandex_storage_h 
Traceback (most recent call last):
  File "<ipython-input-2-8cf6b50de5fc>", line 5, in <module>
    img_to_upload = utils_db.select_img_to_yandex_storage_upload()
  File "data/utils_db.py", line 58, in select_img_to_yandex_storage_upload
    with closing(psycopg2.connect(**params_db)) as conn:
  File "/usr/local/lib/python3.6/dist-packages/psycopg2/__init__.py", line 126, in connect
    conn = _connect(dsn, connection_factory=connection_factory, **kwasync)
psycopg2.OperationalError: could not connect to server: Connection refused
	Is the server running on host "rc1a-sgxb6yanrh3pkjcs.mdb.yandexcloud.net" (10.128.0.6) and accepting
	TCP/IP connections on port 6432?

------------
 2019-06-01 15:54:54,177 - vk_exception_h - ERROR - error uploader_to_yandex_storage_h 
Traceback (most recent call last):
  File "<ipython-input-2-8cf6b50de5fc>", line 5, in <module>
    img_to_upload = utils_db.select_img_to_yandex_storage_upload()
  File "data/utils_db.py", line 58, in select_img_to_yandex_storage_upload
    with closing(psycopg2.connect(**params_db)) as conn:
  File "/usr/local/lib/python3.6/dist-packages/psycopg2/__init__.py", line 126, in connect
    conn = _connect(dsn, connection_factory=connection_factory, **kwasync)
psycopg2.OperationalError: could not connect to server: Connection refused
	Is the server running on host "rc1a-sgxb6yanrh3pkjcs.mdb.yandexcloud.net" (10.128.0.6) and accepting
	TCP/IP connections on port 6432?

------------
 2019-06-01 15:54:54,625 - vk_exception_h - ERROR - error uploader_to_yandex_storage_h 
Traceback (most recent call last):
  File "<ipython-input-2-8cf6b50de5fc>", line 5, in <module>
    img_to_upload = utils_db.select_img_to_yandex_storage_upload()
  File "data/utils_db.py", line 58, in select_img_to_yandex_storage_upload
    with closing(psycopg2.connect(**params_db)) as conn:
  File "/usr/local/lib/python3.6/dist-packages/psycopg2/__init__.py", line 126, in connect
    conn = _connect(dsn, connection_factory=connection_factory, **kwasync)
psycopg2.OperationalError: could not connect to server: Connection refused
	Is the server running on host "rc1a-sgxb6yanrh3pkjcs.mdb.yandexcloud.net" (10.128.0.6) and accepting
	TCP/IP connections on port 6432?

